<?xml version="1.0" encoding="utf-8"?>
<!-- =================================================================================== -->
<!-- |    This document was autogenerated by xacro from robot_builder.xacro            | -->
<!-- |    EDITING THIS FILE BY HAND IS NOT RECOMMENDED                                 | -->
<!-- =================================================================================== -->
<robot name="robot_v1" xmlns:xacro="http://www.ros.org/wiki/xacro">
  <!-- XACRO macro function declarations -->
  <link name="base_link">
    <!-- Inertia properties here -->
    <inertial>
      <origin rpy="0.0 0.0 0.0" xyz="0.0 0.0 0.0"/>
      <mass value="0.0"/>
      <inertia ixx="0.0" ixy="0.0" ixz="0.0" iyy="0.0" iyz="0.0" izz="0.0"/>
    </inertial>
    <visual>
      <origin rpy="0.0 0.0 0.0" xyz="0.0 0.0 0.0"/>
      <geometry>
        <box size="0.1 0.2 0.3"/>
      </geometry>
      <material name="base_material">
        <color rgba="0.0 1.0 0.0 1.0"/>
      </material>
    </visual>
    <collision>
      <origin rpy="0.0 0.0 0.0" xyz="0.0 0.0 0.0"/>
      <geometry>
        <box size="0.1 0.2 0.3"/>
      </geometry>
    </collision>
  </link>
  <link name="link1">
    <inertial>
      <!--    Expected tags
                    <origin xyz="0.0 0.0 0.0" rpy="0.0 0.0 0.0"/>
                    <mass value="0.0"/>
                    <inertia ixx="0.0" ixy="0.0" ixz="0.0" iyy="0.0" iyz="0.0" izz="0.0"/>
                -->
      <origin rpy="0.0 0.0 0.0" xyz="0.0 0.0 0.0"/>
      <mass value="0.0"/>
      <inertia ixx="0.0" ixy="0.0" ixz="0.0" iyy="0.0" iyz="0.0" izz="0.0"/>
    </inertial>
    <visual>
      <origin rpy="0.0 0.0 0.0" xyz="0.0 0.0 0.0"/>
      <geometry>
        <mesh filename="package://robot_viz/urdf/meshes/link1_body.stl" scale="0.001 0.001 0.001"/>
      </geometry>
      <material name="link_material">
        <color rgba="1.0 0.0 0.0 1.0"/>
      </material>
    </visual>
    <collision>
      <origin rpy="0.0 0.0 0.0" xyz="0.0 0.0 0.0"/>
      <geometry>
        <box size="1 0.2 0.2"/>
      </geometry>
    </collision>
  </link>
  <joint name="joint_base_link_link1" type="revolute">
    <origin rpy="0.0 0.0 0.0" xyz="0.0 0.0 0.15"/>
    <parent link="base_link"/>
    <child link="link1"/>
    <axis xyz="0.0 0.0 1.0"/>
    <limit effort="10" lower="0" upper="6.28318530718" velocity="10"/>
  </joint>
  <link name="link2">
    <inertial>
      <!--    Expected tags
                    <origin xyz="0.0 0.0 0.0" rpy="0.0 0.0 0.0"/>
                    <mass value="0.0"/>
                    <inertia ixx="0.0" ixy="0.0" ixz="0.0" iyy="0.0" iyz="0.0" izz="0.0"/>
                -->
      <origin rpy="0.0 0.0 0.0" xyz="0.0 0.0 0.0"/>
      <mass value="0.0"/>
      <inertia ixx="0.0" ixy="0.0" ixz="0.0" iyy="0.0" iyz="0.0" izz="0.0"/>
    </inertial>
    <visual>
      <origin rpy="0.0 0.0 0.0" xyz="0.0 0.0 0.0"/>
      <geometry>
        <mesh filename="package://robot_viz/urdf/meshes/link1_body.stl" scale="0.001 0.001 0.001"/>
      </geometry>
      <material name="link_material">
        <color rgba="1.0 0.0 0.0 1.0"/>
      </material>
    </visual>
    <collision>
      <origin rpy="0.0 0.0 0.0" xyz="0.0 0.0 0.0"/>
      <geometry>
        <box size="1 0.2 0.2"/>
      </geometry>
    </collision>
  </link>
  <joint name="joint_link1_link2" type="revolute">
    <origin rpy="0.0 -1.57079632679 0.0" xyz="1.0 0.0 0"/>
    <parent link="link1"/>
    <child link="link2"/>
    <axis xyz="0.0 0.0 1.0"/>
    <limit effort="10" lower="0" upper="6.28318530718" velocity="10"/>
  </joint>
</robot>
